## Chapter 08 예외처리

### 1. 예외처리(exception handling)

#### 1.1 프로그램 오류

프로그램이 실행 중 어떤 원인에 의해서 오작동을 하거나 비정상적으로 종료되는 경우가 있는데 이러한 결과를 초래하는 원인을 `프로그램 에러` 또는 `오류`라고한다.

발생시점에 따라 에러가 나뉨

```
- 컴파일 에러(compile-time error) 컴파일 시에 발생하는 에러
- 런타임 에러(runtime error)		 실행 시에 발생하는 에러
- 논리적 에러(logical error)		 실행은 되지만, 의도와 다르게 동작하는 것
  	예) 게임 프로그램에서 비행기가 총알을 맞아도 죽지 않는 경우
```

자바에서는 실행 시(runtime) 발생할 수 있는 프로그램 오류를 두 가지로 구분함

```
에러(error)	  프로그램 코드에 의해서 수습될 수 없는 심각한 오류
예외(exception) 프로그램 코드에 의해서 수습될 수 있는 다소 미약한 오류
```

**다시 보는 컴파일러 역할**

- 구문체크
- 번역
- 소스코드의 최적화
  - int  i = 3+5 , 3+5를 컴파일러가 8로 처리해놓음
- 생략된 코드 추가
  - 모든 클래스는 extends object가 생략되어 있음 

#### 1.2 예외 클래스의 계층구조

Exception, error 모두 런타임 에러이다.

![](C:\Users\이진형\바탕 화면\TIL\Java문법\img\08-12.png)

![](C:\Users\이진형\바탕 화면\TIL\Java문법\img\08-12-2.png)

예외 클래스들은 다음과 같이 두 그룹으로 나뉜다.

```
1. Exception클래스와 그 자손들(그림 윗부분, RuntimeException과 자손들은 제외)
2. RuntimeException클래스와 그 자손들(그림 아랫부분)
```

```
Exception클래스들			사용자의 실수와 같은 외적인 요인에 의해 발생하는 예외
	- 존재하지 않는 파일의 이름을 입력한 경우(FileNotFoundException)
    - 실수로 클래스의 이름을 잘못 적은 경우(ClassNotFoundException)
    - 입력한 데이터 형식이 잘못된 경우(DataFormatException)

RuntimeException클래스들	프로그래머의 실수로 발생하는 예외
	- 배열의 범위를 벗어나는 경우(ArrayIndexOutOfBoundsException)
	- 값이 null인 참조변수의 멤버를 호출하려 한 경우(NullPointerException)
	- 클래스간의 형변환을 잘못한 경우(ClassCastException)
	- 정수를 0으로 나누는 경우(ArithmeticException)

```

#### 1.3 예외처리하기 - try-catch문

```
예외처리(exception handling)
	정의 - 프로그램 실행 시 발생할 수 있는 예외에 대비한 코드를 작성하는것
	목적 - 프로그램의 비정상 종료를 막고, 정상적인 실행상태를 유지하는 것
```

발생한 예외를 처리하지 못하면, 프로그램은 비정상 종료된다.

처리되지 못한 예외(uncaught exception)는 JVM의 '예외처리기(UncaughtExceptionHandler)'가 받아서 예외의 원인을 화면에 출력한다.

```java
// 예외 처리하기 위한 try-catch문
// if 문과 달리, try블럭이나 catch블럭 내에 포함된 문장이 하나뿐이어도 괄호{}를 생략할 수 없다.

try{
	// 예외가 발생할 가능성이 있는 문장들을 넣는다.
} catch(Exception e1){
	// Exception e1이 발생했을 경우, 이를 처리하기 위한 문장을 적는다.
} catch(Exception e2){
	// Exception e2이 발생했을 경우, 이를 처리하기 위한 문장을 적는다.
} catch(Exception e3){
	// Exception e3이 발생했을 경우, 이를 처리하기 위한 문장을 적는다.
}

```

하나 이상의 catch블럭이 올 수 있으며, 이 중 발생한 예외의 종류와 일치하는 단 한 개의 catch블럭만 수행된다.만약 일치하는 catch블럭이 없으면 예외는 처리되지 않는다.

예제1

```java
class ExceptionEx1 {
    public static void main(String[] args) {
        try{
            try{} catch(Exception e){}
        }catch(Exception e){			// 참조변수 e는 catch 블럭 내에서만 유효
            try{} catch(Exception e){}	// 에러. 변수 e가 중복 선언됨.
        }
        
        try{
            
        }catch (Exception e){	// 참조변수 e는 catch 블럭 내에서만 유효
            
        }
    }
}
```

catch블럭의 괄호 내에 선언된 변수는 catch블럭 내에서만 유효하다. 그래서 위의 모든 catch블럭에 참조변수'e'하나 만을 사용해도 된다. 그러나 catch블럭 내에 또 하나의 try-catch문이 포함된 경우, 같은 이름의 참조변수를 사용 못함. 각 catch블럭에 선언된 두 참조변수의 영역이 서로 겹치므로 다른이름을 사용해야만 서로 구별되기 때문에

예제2

```java
class ExceptionEx2 {
    public static void main(String[] args) {
        int number = 100;
        int result = 0;

        for(int i=0;i<10;i++){
            result = number /(int)(Math.random()*10);
            System.out.println(result);
        }
    }
}
/* 결과
	11
	20
	25
	33
	14
	Exception in thread "main" java.lang.ArithmeticException: / by zero
		at ExceptionEx2.main(ExceptionEx2.java:7)
*/
```

이 결과를 통해 알수 있는것

- `by zero`  : 0으로 나누려 했기 때문에 예외가 발생
- `ArithmeticException` : 산술연산과정에서 오류가 발생했고
- `at ExceptionEx2.main(ExceptionEx2.java:7)` : 발생위치는 ExceptionEx2클래스의 main메서드(ExceptionEx2.java의 7번쨰 라인)

예제3(예제2에 try-catch문을 추가)

```java
class ExceptionEx3 {
    public static void main(String[] args) {
        int number = 100;
        int result = 0;

        for(int i =0; i<10; i++){
            try{
                result = number/(int)(Math.random()*10);
                System.out.println(result);
            }catch (ArithmeticException e){     // ArithmeticException이 발생하면 실행되는 코드
                System.out.println("0");
            }
        }
    }
}
/* 결과
14
0
16
14
100
11
0
16
14
14
*/

```

예외처리를 해서 작업을 모두 마치고 정상적으로 종료된 모습이다.

#### 1.4 try-catch문에서의 흐름

```
try블럭 내에서 예외가 발생한 경우,
1. 발생한 예외와 일치하는 catch블럭이 있는지 확인한다.
2. 일치하는 catch블럭을 찾게 되면, 그 catch블럭 내의 문장들을 수행하고 전체 try-catch문을 빠저나가서 그 다음 문장을 계속해    서 수행한다. 만일 일치하는 catch블럭을 찾지 못하면, 예외는 처리되지 못한다.

try블럭 내에서 예외가 발생하지 않은 경우,
1. catch블럭을 거치지 않고 전체 try-catch문을 빠져나가서 수행을 계속한다.
```

예외가 발생하지 않은 경우

```java
class ExceptionEx4 {
    public static void main(String[] args) {
        System.out.println(1);
        System.out.println(2);
        try{
            System.out.println(3);
            System.out.println(4);
        }catch(Exception e){
            System.out.println(5);   // 예외가 발생하지 않았기에 실행되지 않음(catch블럭의 문장이 실행x)
        }
        System.out.println(6);
    }
}
/* 결과
	1
	2
	3
	4
	6
*/

```

예외가 발생한 경우

```java
class ExceptionEx5 {
    public static void main(String[] args) {
        System.out.println(1);
        System.out.println(2);
        try{
            System.out.println(3);
            System.out.println(0/0);	// 예외 발생!! 이후에 있는 try블럭의 문장들은 수행x,
            							// 예외에 해당하는 catch블럭으로 이동하여 문장들을 수행
            
            System.out.println(4);      // 실행되지 않는다.
        }catch(Exception e){
            System.out.println(5);
        }
        System.out.println(6);
    }
}
/* 결과
	1
	2
	3
	5
	6
*/
```

#### 1.5 예외의 발생과 catch블럭

catch블럭 괄호()내에는 처리하고자 하는 에외와 같은 타입의 참조변수 하나를 선언해야한다.

예외가 발생하면, 발생한 예외에 해당하는 클래스의 인스턴스가 만들어진다. 만약 ArithmeticException이 발생하면 ArithmeticException인스턴스가 생성된다. 이 인스턴스에는 예외 정보가 들어있다. 예외가 발생한 문장이 try블럭에 포함되어 있다면, 이 예외를 처리할 수 있는 catch 블럭이 있는지 찾게 된다. 

먼저 catch블럭부터 차례로 내려가면서 catch블럭의 괄호()내에 선언된 참조변수의 종류와 생성된 예외클래스의 인스턴스에 instatnce of 연산자를 이용해서 검사하게 되는데 검사결과가 true인 caatch블럭을 만날 때까지 검사를 계속한다.

검사 결과가 true인 catch블럭을 찾게되면 블럭에 있는 문장들을 모두 수행한 후에 try-catch문을 빠져나가고 예외는 처리됨

만약 검사결과가 true인 catch블럭이 없으면 예외는 처리되지 않고 비정상 종료된다.

- 모든 예외 클래스는 Exception클래스의 자손이므로, catch블럭의 괄호에 Exception클래스 타입의 참조변수를 선언해 놓으면 어떤 종류의 예외가 발생하더라도 이 catch블럭에 의해서 처리된다.

  ```java
  try{
  	
  }catch(Exception e){
  	// 예외처리 문장
  }
  ```

두개이상의 catch문이 있는경우

```java
class ExceptionEx7 {
    public static void main(String[] args) {
        System.out.println(1);
        System.out.println(2);
        try{
            System.out.println(3);
            System.out.println(0/0);
            System.out.println(4);		// 실행되지 않는다.
        }catch (ArithmeticException ae){
            if(ae instanceof ArithmeticException)
                System.out.println("true");
            System.out.println("ArithmeticException");
        }catch (Exception e){
        // 1번째 catch문에 쓰인 참조변수를 제외하고(ArithmeticException) 모든 예외가 처리된다.
            System.out.println("Exception");   
            
        }
        System.out.println(6);
    }
}
```

1. try블럭에서 System.out.println(0/0)부분에서 ArithmeticException이 발생
2. catch블럭을 하나씩 차례로 검사하다가 첫 번째 검사에서 일치하는 catch블럭을 찾았기에 두 번째 catch블럭은 검사하지 않는다.
   - 만약 try블럭 내에서 AirthmeticException이 아닌 다른 종류의 예외가 발생한 경우에는 두 번째 catch블럭인 Exception클래스 타입의 참조변수를 선언한 곳에서 처리되었을 것이다.
3. 첫 번째 catch블럭의 문장 수행후 try-catch문을 벗어남
4. 마지막 System.out.println(6) 수행후 정상적인 종료

**printStackTrace()와 getMessage()**

```
printStackTrace() 예외발생 당시의 호출스택(Call statck)에 있었던 메서드의 정보와 예외 메세지를 화면에 출력한다.

getMessage()	  발생한 예외클래스의 인스턴스에 저장된 메시지를 얻을 수 있다.
```

```java
class ExceptionEx8 {
    public static void main(String[] args) {
        System.out.println(1);
        System.out.println(2);
        try{
            System.out.println(3);
            System.out.println(0/0);    // 예외 발생!!
            System.out.println(4);      // 실행되지 않는다.
        }catch (ArithmeticException ae) {
            ae.printStackTrace();
            System.out.println("예외메시지 : "+ae.getMessage());
        }
        System.out.println(6);
    }
}

/* 결과
1
2
3
java.lang.ArithmeticException: / by zero
	at ExceptionEx8.main(ExceptionEx8.java:7)
예외메시지 : / by zero
6

Process finished with exit code 0 정상종료 
*/ 
```

**멀티 catch블럭**

JDK1.7부터 여러 catch블럭을 `|`기호를 이용해서 하나의 catch블럭으로 합칠 수 있게 됨

`|`기호로 연결할 수 있는 예외 클래스의 개수 제한x

장점 : 중복된 코드를 줄일 수 있다..

```java
try{
	...
}catch(ExceptionA e){
	e.printStackTrace();
}catch(ExceptionB e2){
	e2.printStackTrace();
}
```

위코드를 하나의 catch블럭으로 합치면

```java
try{
	...
}catch(ExceptionA | ExceptionB e){
	e.printStackTrace();
}
```

만약 연결된 예외 클래스가 조상과 자손의 관계에 있다면 컴파일에러

```java
try{
	...
}catch(ParentException | ChildException e){	// 에러!
	e.printStackTrace();
}
```

다음과 같이 조상 클래스만 써주는 것과 똑같기 때문에 불필요한 코드제거하라고 에러가 발생한다.

```java
try{
	...
}catch(ParentException e){	
	e.printStackTrace();
}
```

```java
try{
	...
}catch(ExceptionA | ExceptionB e2){
	e.methodA(); 	// 에러. Exception A,B의 공통멤버만 사용가능하다. ExceptionA에만 선언된 methodA()는 호출불가
	
	// 만일 필요하다면 다음과 같이 하면되지만 이렇게 할빠에 그냥 여러 catch블럭으로 쓰는게 나음
	if(e instatnceof ExceptionA){
        // e의타입은 ExceptionA, ExceptionB의 공통조상이기다. 그래서  (ExceptionA)로 타입캐스팅한것
		ExceptionA e1 = (ExceptionA)e;//
		e1.methodA();
	}else{		// if(e isntanceof ExceptionB)
	
	}
	e.printStackTrace();
	
}
```

멀티catch블럭에 선언된 참조변수 e는 상수이므로 값을 변경할수 없다.(여러 catch블럭이 하나의 참조변수를 공유하기 때문에 생기는 제약) 참조변수의 값을 바꿀 일은 없을 것이니 걱정x. 

#### 1.6 예외 발생시키기

프로그래머가 고의로 예외를 발생시키는법

```
1. 연산자 new를 이용해서 발생시키려는 예외 클래스의 객체를 만든 다음
	Exception e = new Exception("고의로 발생시켰음");

2. 키워드 throw를 이용해서 예외를 발생시킨다.
	throw e;

다음과 같이 위 두 줄을 한 줄로 줄여 쓸 수 있다.
	throw new Exception("고의로 발생시켰음");

Exception인스턴스를 생성할때, 생성자에 String을 넣어 주면, 이 String이 Exception인스턴스에 메시지로 저장된다.
```

```java
class ExceptionEx9 {
    public static void main(String[] args) {
        try{
            Exception e = new Exception("고의로 발생시켰음.");
            throw e;
        }catch (Exception e){
            System.out.println("에러 메시지 : "+e.getMessage());
            e.printStackTrace();
        }
        System.out.println("프로그램이 정상 종료되었음.");
    }
}
/* 결과

	에러 메시지 : 고의로 발생시켰음.
	프로그램이 정상 종료되었음.
	java.lang.Exception: 고의로 발생시켰음.
		at ExceptionEx9.main(ExceptionEx9.java:4)
Process finished with exit code 0
*/
```

![](C:\Users\이진형\바탕 화면\TIL\Java문법\img\08-16.png)

- checked예외

  Exception클래스들이 발생할 가능성이 있는 문장들에 대해 예외처리를 해주지 않으면  컴파일 조차 되지 않는다. 

  ```java
  class ExceptionEx10 {
      public static void main(String[] args) {
          throw new Exception();      // Exception예외를 고의로 발생시킨다.
      }
  }
  /* 결과 : 에러처리가되어야 할 부분에 예외처리가 되어 있지 않다는 에러이다.
  C:\Users\이진형\바탕 화면\자바\Chapter 08\src\ExceptionEx10.java:3:9
  java: unreported exception java.lang.Exception; must be caught or declared to be thrown
  */
  ```

- unchecked예외

  RuntimeException클래스들에 해당하는 예외는 프로그래머에 의해 실수로 발생하는 것들이기 때문에 <u>예외처리를 강제하지 않는다.</u>

  그래서 <u>이전의 예제와 달리 성공적으로 컴파일 된 것이다</u>. 그러나 실행하면, 위의 결과처럼 RuntimeException이 발생하여 비정상적으로 종료된다.

  ```java
  class ExceptionEx11 {
      public static void main(String[] args) {
          throw new RuntimeException();       // RuntimeException을 고의로 발생시킨다.
      }
  }
  /* 결과
  Exception in thread "main" java.lang.RuntimeException
  	at ExceptionEx11.main(ExceptionEx11.java:3)
  
  Process finished with exit code 1
  */
  ```

  만약 RuntimeException클래스들에 속하는 예외가 발생할 가능성이 있는 코드에도 예외처리를 필수로 해야 한다면, 아래 코드와 같이 참조 변수와 배열이 사용되는 모든 곳에 예외처리를 해주어야 할 것이다.

  ```java
  try{
  	int [] arr = new int[10];
  	
  	System.out.println(arr[0]);
  } catch(ArrayIndexOutOfBoundsException ae){
  		...
  } catch(NullPointerException ne){
  		...
  }
  ```

#### 1.7 메서드에 예외 선언하기

-예외처리 하는법

1. try-catch(직접처리)
2. 예외 선언하기(폭탄처럼 예외를 떠넘기는 것)
3. 은폐,무시(빈 catch블럭 사용)



-예외 선언하는 법

`throws`를 사용해서 메서드 내에서 발생할 수 있는 예외를 적어주면 된다.

메서드에 예외를 선언할 때 일반적으로 RuntimeException클래스들은 적지 않는다. 보통 반드시 처리해주어야 하는 예외만 선언

```java
// 메서드를 사용하려는 사람이 메서드의 선언부를 보았을 때, 이 메서드를 사용하기 위해서는
// 어떠한 예외들이 처리되어야 하는지 쉽게 알 수 있다.
void method() throws Exception1, Exception2, ... ExceptionN{
	// 메서드 내용
}
```

모든 예외의 최고조상인 Exception클래스를 메서드에 선언

```java
void method() throws Exception{
	// 메서드의 내용
}
```

- 이 메서드는 모든 종류의 예외가 발생할 가능성이 있다는 뜻
- 이 예외뿐만 아니라 그 자손타입의 예외까지도 발생할 수 있다는 점에 주의
  - 오버라이딩할 때는 선언된 예외의 개수가 아니라 상속관계까지 고려해야한다.
  - 오버라이딩 조건 
    1. 선언부 일치
    2. 접근제어자 좁게 x
    3. 조상보다 많은 예외선언 x



예외를 메서드의 throws에 명시하는 것은 예외를 처리하는 것이 아니라, 자신(예외가 발생할 가능성이 있는 메서드)을 호출한 메서드에게 예외를 전달하여 예외처리를 떠맡기는 것이다. 

```java
class ExceptionEx12 {
    public static void main(String[] args)  throws Exception{
        method1();
    }
    static void method1() throws Exception{
        method2();
    }
    static void method2() throws Exception{
        throw new Exception();
    }
}
/* 
1. 예외가 발생했을 때, 모두 3개의 메서드(main,method1,method2)가 호출스택에 있었으며,
2. 예외가 발생한 곳은 제일 윗줄에 있는 method2()라는 것과
3. main메서드가 method1()을, 그리고 method1()은 method2()를 호출했다는 것을 알 수 있다.
실행 결과
Exception in thread "main" java.lang.Exception
	at ExceptionEx12.method2(ExceptionEx12.java:9)
	at ExceptionEx12.method1(ExceptionEx12.java:6)
	at ExceptionEx12.main(ExceptionEx12.java:3)

Process finished with exit code 1
*/
```

위 예제 실행 결과 과정

1. method2()에서 `throw new Exception();` 에 의해 예외가 강제적으로 발생했으나, try-catch문으로 예외처리를 해주지 않았으므로, method2()는 종료되면서 예외를 자신을 호출한 method1()에게 넘겨준다.
2. method1()에서도 역시 예외처리를 해주지 않았으므로 종료되면서 main메서드에게 예외를 넘겨준다.
3. main메서드에서 조차 예외처리를 해주지 않았으므로 main메서드가 비정상조료 되고, 예외는 JVM에게 넘김
4. JVM 기본 예외처리기가 실행결과를 출력함.
5. 결국 예외가 처리되지 못했다. <u>어느 한 곳에서는 반드시 try-catch문으로 예외를 처리해주어야 한다.</u>



예외가 발생한 메서드에서 직접 예외 처리한 경우1

​		 main메서드에서는 예외가 발생했다는 사실조차 모르게 된다.

```java
public class ExceptionEx13 {
    public static void main(String[] args) {
        method1();
    }
    static void method1(){
        try{
            throw new Exception();
        }catch(Exception e){
            System.out.println("method1메서드에서 예외가 처리되었습니다.");
            e.printStackTrace();
        }
    }
}
/* 결과
method1메서드에서 예외가 처리되었습니다.
java.lang.Exception
	at ExceptionEx13.method1(ExceptionEx13.java:7)
	at ExceptionEx13.main(ExceptionEx13.java:3)
*/
```

메서드를 호출한 메서드(main메서드)에서 처리한 경우1

​		예외가 발생한 method1()메서드에서 자신을 호출하는 main메서드에 예외를 전달했으며, 호출한 메서드(main)에서는 try-catch문으		예외처리를 했다.

```java
public class ExceptionEx14 {
    public static void main(String[] args) {
      try{
          method1();
      }catch(Exception e){
          System.out.println("main메서드에서 예외가 처리되었습니다.");
          e.printStackTrace();
      }
    }
    static void method1() throws Exception{
            throw new Exception();
        }
}
/* 결과
main메서드에서 예외가 처리되었습니다.
java.lang.Exception
	at ExceptionEx14.method1(ExceptionEx14.java:11)
	at ExceptionEx14.main(ExceptionEx14.java:4)
*/
```

예외가 발생한 메서드에서 직접 예외 처리한 경우2

이 예제와 같이 예외가 발생한 메서드 내에서 자체적으로 처리해도 되는것은 메서드 내에서 try-catch문 사용해서 처리

```java
import java.io.*;
class ExceptionEx15 {
    public static void main(String[] args) {
        // command line에서 입력받은 값을 이름으로 갖는 파일을 생성한다.
        File f = createFile(args[0]);
        System.out.println(f.getName() + " 파일이 성공적으로 생성되었습니다.");
    }
    
    static File createFile(String fileName){
        try{
            if(fileName==null || fileName.equals(""))
                throw new Exception("파일이름이 유효하지 않습니다.");
        }catch (Exception e){
            // fileName이 부적절한 경우, 파일이름을 '제목없음.txt'로 한다.
            fileName="제목없음.txt";
        }finally {
            File f = new File(fileName);
            createNewFile(f);
            return f;
        }
    }
    // finally블럭 내에 또다시 try-catch문으로 처리하면 복잡해저서 간단하게 하기 위해 내부적으로 예외처리를 한createNewFie(File f)메서드를 만들어서 사용함
    static void createNewFile(File f){
        try{						
            f.createNewFile();      // createNewFile()은 예외가 선언된 메서드이므로 try-catch문을 사용함
        }catch (Exception e){}
    }
}
```

메서드를 호출한 메서드(main메서드)에서 처리한 경우2

이 예제와 같이 메서드에 호출 시 넘겨받아야 할 값(fileName)을 다시 받아야 하는 경우(메서드 내에서 자체적으로 해결이 안 되는 경우)에는 예외를 메서드에 선언해서, 호출한 메서드를 처리해야한다.

```java
import java.io.*;

class ExceptionEx16 {
    public static void main(String[] args) {
        try{
            File f = createFile(args[0]);
            System.out.println(f.getName() + " 파일이 성공적으로 생성되었습니다.");
        }catch (Exception e){
            System.out.println(e.getMessage()+"다시 입력해 주시기 바랍니다.");
        }
    }

    static File createFile(String fileName) throws Exception{
        if(fileName==null || fileName.equals(""))
            throw new Exception("파일이름이 유효하지 않습니다.");
        File f = new File(fileName);
 /* 위 예제와 달리 createFile메서드에 예외를 선언했기(throws) 때문에, File클래스의 create NewFile()에 대한
    예외처리를 하지 않아도 되므로 createNewFile(File f)메서드를 굳이 따로 만들지 않았다.*/
        f.createNewFile();
        return f;
        }
    }
```

#### 1.8 finally블럭

예외의 발생여부에 상관없이 실행되어야할 코드를 포함시킬 목적으로 사용된다.

```java
// 예외 발생한 경우 try->catch->finally순으로 실행
// 예외 발상하지 않은 경우 try-> finally순으로 실행

try{
	// 예외가 발생할 가능성이 있는 문장들을 넣는다.
} catch (Exception e1){
	// 예외처리를 위한 문장을 적는다.
} finally{
	// 예외의 발생여부에 관계없이 항상 수행되어야하는 문장들을 넣는다.
	// finally블럭은 try-catch문의 맨 마지막에 위치해야한다.
}
```

```java
class FinallyTest {
    public static void main(String[] args) {
        try{
            startInstall();         // 프로그램 설치에 필요한 준비를 한다.
            copyFiles();            // 파일들을 복사한다.
            deleteTempFiles();      // 프로그램 설치에 사용된 임시파일들을 삭제한다.
        }catch (Exception e){
            e.printStackTrace();
            deleteTempFiles();      // 프로그램 설치에 사용된 임시파일들을 삭제한다.
        }
    }

    static void startInstall(){
        /* 프로그램 설치에 필요한 준비를 하는 코드를 적는다.*/
    }
    static void copyFiles(){ /* 파일들을 복사하는 코드를 적는다. */ }
    static  void deleteTempFiles(){/* 임시파일들을 삭제하는 코드를 적는다.*/}
}
```

위 예제는 try블럭의 문장을 수행하는 동안에, 예외의 발생여부에 관계없이 deleteTempFiles()메서드가 실행되어야 한다.

이럴때 finally블럭을 사용한다.

```java
class FinallyTest2 {
    public static void main(String[] args) {
        try{
            startInstall();         // 프로그램 설치에 필요한 준비를 한다.
            copyFiles();            // 파일들을 복사한다.
        }catch (Exception e){
            e.printStackTrace();
        }finally {
            deleteTempFiles();
        }
    }

    static void startInstall(){
        /* 프로그램 설치에 필요한 준비를 하는 코드를 적는다.*/
    }
    static void copyFiles(){ /* 파일들을 복사하는 코드를 적는다. */ }
    static  void deleteTempFiles(){/* 임시파일들을 삭제하는 코드를 적는다.*/}
}
```

try블럭에서 return 문이 실행되는 경우에도 finally블럭의 문장들이 먼저 실행된 후에, 현재 실행 중인 메서드를 종료한다.

```java
class FinallyTest3 {
    public static void main(String[] args) {
        FinallyTest3.method1();
        System.out.println("method1()의 수행을 마치고 main메서드로 돌아왔습니다.");
    }
    static void method1(){
        try{
            System.out.println("method1()이 호출되었습니다.");
            return;     // 현재 실행 중인 메서드를 종료한다.
        }catch (Exception e){
            e.printStackTrace();
        }finally {
            System.out.println("method1()의 finally블럭이 실행되었습니다.");
        }
    }
}
/* 결과
method1()이 호출되었습니다.
method1()의 finally블럭이 실행되었습니다.
method1()의 수행을 마치고 main메서드로 돌아왔습니다.
*/
```

#### 1.9 자동 자원 반환 -try-with-resources문

이1.9챕터는 나중에 자세히 배우니 이런 것도 있다는 정도로만 가볍게 넘어감

JDK1.7부터 try-with-resources문이라는 try-catch문의 변형이 새로 추가됨. 입출력(I/0)과 관련된 클래스를 사용할 때 유용하다.

입출력에 사용되는 클래스 중에는 사용한 후에 꼭 닫아 줘야 하는 것들이 있다. 그래야 사용했던 자원(resources)이 반환되기 때문이다.

```java
try{
	fis = new FileInputStream("score.dat");
	dis = new DataInputStream(fis);
		 ...
} catch (IOException ie){
	ie.printStackTrace();
} finally{
	dis.close();	// 작업 중에 예외가 발생하더라도, dis가 닫히도록 finally블럭에 넣음.
}
```

위 코드는 문제 없어보이지만, 이때 close()가 예외를 발생시킬 수 있다. 그래서 finally 블럭 안에 try-catch문을 추가해서 close()에서 발생할 수 있는 예외를 처리하도록 변경해야한다. 그러나 코드가 복잡해져서 보기에 좋지 않다.

또 try블럭과 finally블럭에서 모두 예외가 발생하면, try블럭의 예외는 무시된다.

```java
try{
	fis = new FileInputStream("score.dat");
	dis = new DataInputStream(fis);
		 ...
} catch (IOException ie){
	ie.printStackTrace();
} finally{
	try{
		if(dis!=null)
			dis.close();
	} catch(IOException ie){
		ie.printStackTrace();
	}
}
```

이러한 점을 개선하기위해 try-with-resources문이 추가된 것이다.

```
try(FileInputStream fis = new FileInputStream("score.dat");
	DataInputStream dis = new DataInputStream(fis)){
   
   while(true){
   	  score = dis.readInt();
      System.out.println(score);
      sum+=score;
   }
} catch (EOFFxception e){
	System.out.println("점수의 총합은 "+ sum + "입니다.");
} catch (IOException ie){
	ie.printStackTracce();
}
```

위 코드처럼 try-with-resources문의 괄호()안에 객체를 생성하는 문장을 넣으면, 이 객체는 따로 close()를 호출하지 않아도 try블럭을 벗어나는 순간 자동적으로 close()가 호출된다. 그다음 catch블럭 또는 finally블럭이 수행된다. try블럭의 괄호()안에 선언된 변수는 try블럭 내에서만 사용가능

이처럼 try-with-resources문에 의해 자동으로 객체의 close()가 호출될 수 있으려면 클래스가 AutoCloseable이라는 인터페이스를 구현한 것이어야 한다.

```java
// 이 인터페이스는 각 클래스에서 적절히 자원 반환작업을 하도록 구현되어 있다.
public interface AutoCloseable{
	void close() throws Exception;
}
```

```java
class TryWithResourceEx {
    public static void main(String[] args) {
        // 첫 번째 try-catch문 close()에서만 예외 발생
        try(CloseableResource cr = new CloseableResource()){		// try블럭을 벗어나면 close()가 호출된다.
            cr.exceptionWork(false);    // 예외가 발생하지 않는다.
        } catch(WorkException e){
            e.printStackTrace();
        } catch (CloseException e){
            e.printStackTrace();
        }
        System.out.println();
        // 두 번째 try-catch문 exceptionWork와 close()에서 모두 예ㄹ외 발생
        try(CloseableResource cr = new CloseableResource()){
            cr.exceptionWork(true);     // 예외가 발생한다.
        }catch(WorkException e){
            e.printStackTrace();
        }catch (CloseException e){
            e.printStackTrace();
        }
    }
}

class CloseableResource implements AutoCloseable{		// 자원 반환 하도록 구현되어있다.
    public void exceptionWork(boolean exception) throws WorkException{
        System.out.println("exceptionWork("+exception+")가 호출됨");

        if(exception)
            throw new WorkException("WorkException발생!!!");
    }
    public void close() throws CloseException{
        System.out.println("close()가 호출됨");
        throw new CloseException("CloseException발생!!!");
    }
}

class WorkException extends Exception{      // 사용자정의 예외 만들기
    WorkException(String msg){
        super(msg);
    }
}
class CloseException extends Exception{     // 사용자정의 예외 만들기
    CloseException(String msg){
        super(msg);
    }
}
/* 결과
exceptionWork(false)가 호출됨
close()가 호출됨
CloseException: CloseException발생!!!
	at CloseableResource.close(TryWithResourceEx.java:30)
	at TryWithResourceEx.main(TryWithResourceEx.java:5)
	
exceptionWork(true)가 호출됨
close()가 호출됨
WorkException: WorkException발생!!!
	at CloseableResource.exceptionWork(TryWithResourceEx.java:26)
	at TryWithResourceEx.main(TryWithResourceEx.java:12)
	Suppressed: CloseException: CloseException발생!!!
		at CloseableResource.close(TryWithResourceEx.java:30)
		at TryWithResourceEx.main(TryWithResourceEx.java:11)

```

첫번째는 일반적인 예외가 발생했을 때와 같은 형태로 출력되었지만, 두 번째는 출력형태가 다르다. 먼저 exceptionWork()에서 발생한 예외의 대한 내용이 출력되고, close()에서 발생한 예외는 '억제된(Suppressed)'이라는 의미의 머리말과 함께 출력되었다.

두 예외가 동시에 발생할 수는 없기 때문에, 실제 발생한 예외를 WorkException으로 하고, CloseException은 억제된 예외로 다룬다. 억제된 예외에 대한 정보는 실제로 발생한 예외인 WorkException에 저장된다.

```
Throwable에는 억제된 예외와 관련된 다음과 같은 메서드가 정의되어 있다.

	void addSuppressed(Throwable exception)		억제된 예외를 추가
	Throwable[] getSuppressed()			억제된 예외(배열)를 반환
```

만약 기존의 try-catch문을 사용했다면, 먼저 발생한 WorkException은 무시되고, 마지막으로 발생한 CloseException에 대한 내용만 출력되었을 것이다.

#### 1.10 사용자정의 예외 만들기

프로그래머가 새로운 예외 클래스를 정의하여 사용할 수 있다. 보통 Exception클래스 또는 RuntimeException클래스로부터 상속받아 클래스를 만들지만, 필요에 따라서 알맞은 예외 클래스를 선택할 수 있다.

```java
class MyException extends Exception{
	MyException(String msg){	// 문자열을 매개변수로 받는 생성자
		super(msg)	// 조상인 Exception클래스의 생성자를 호출한다.
	}
}
```

필요하다면, 멤버변수나 메서드를 추가할 수 있다. 또 Exception클래스는 생성 시에 String값을 받아서 메시지로 저장할 수 있는데, 내가 만든 사용자정의 예외 클래스도 메시지를 저장하려면 String을 매개변수로 받는 생성자를 추가해주어야 한다.

```java
class MyException extends Exception{
	// 에러 코드 값을 저장하기 위한 필드를 추가 했다.
	private final int ERR_CODE;	// 생성자를 통해 초기화
	
	MyException(String msg, int errCode){
		super(msg);
		ERR_CODE=errCode;
	}
	MyException(String msg){
		this(msg,100)	// ERR_CODE를 100(기본값)으로 초기화한다.
	}
	public int getErrCode(){	// 에러 코드를 얻을 수있는 메서드 추가
		return ERR_CODE;		// 이 메세드는 주로 getMessage()와 함께 사용될 것이다.
	}
}
```

기존의 예외 클래스는 주로 Exception을 상속받아서 'checked예외'로 작성하는 경우가 많았지만, 요즘은 예외처리를 선택적으로 할 수 있도록 RuntimeException을 상속받아서 작성하는 쪽으로 바뀌고 있다.

checked예외는 반드시 예외처리를 해주어야 하기 때문에 예외처리가 불필요한 경우에도 try-catch문을 넣어서 코드가 복잡해지기 때문



사용자 지정 예외 예제

```java
class NewExceptionTest {
    public static void main(String[] args) {
        try{
            startInstall();     // 프로그램 설치에 필요한 준비를 한다.
            copyFiles();        // 파일들을 복사한다.

        }catch (SpaceException e){
            System.out.println("에러 메시지 : "+e.getMessage());
            e.printStackTrace();
            System.out.println("공간을 확보한 후에 다시 설치하시기 바랍니다.");
        }catch (MemoryException me){
            System.out.println("에러 메시지 : "+ me.getMessage());
            me.printStackTrace();
            System.gc();        // Garbage Collection을 수행하여 메모리를 늘려준다.
            System.out.println("다시 설치를 시도하세요.");
        }finally {
            deleteTempFiles();      // 프로그램에 설치된 임시파일을 삭제한다.
        }
    }
    static void startInstall() throws SpaceException, MemoryException{
        if(!enoughMemory())         // 충분한 설치 공간이 없으면
            throw new SpaceException("설치할 공간이 부족합니다.");
        if(!enoughMemory())         // 충분한 메모리가 없으면
            throw new MemoryException("메모리가 부족합니다.");
    }
    static void copyFiles(){/* 파일들을 복사하는 코드를 적는다. */}
    static void deleteTempFiles(){/* 임시파일들을 삭제하는 코드를 적는다.*/}

    static boolean enoughSpace(){
        // 설치하는데 필요한 공간이 있는지 확인하는 코드를 적는다.
        return false;
    }
    static boolean enoughMemory(){
        // 설치하는데 필요한 메모리공간이 있는지 확인하는 코드를 적는다.
        return true;
    }
}

// 사용자 지정 예외 클래스
class SpaceException extends Exception{
    SpaceException(String msg){
        super(msg);
    }
}
// 사용자 지정 예외 클래스
class MemoryException extends Exception{
    MemoryException(String msg){
        super(msg);
    }
}

/* 결과
에러 메시지 : 설치할 공간이 부족합니다.
공간을 확보한 후에 다시 설치하시기 바랍니다.
SpaceException: 설치할 공간이 부족합니다.
	at NewExceptionTest.startInstall(NewExceptionTest.java:22)
	at NewExceptionTest.main(NewExceptionTest.java:4)
*/
```

#### 1.11 예외 되던지기(exception re-throwing)

예외를 처리한 후에 인위적으로 다시 발생시키는것(예외가 발생한 메서드와 호출한 메서드, 양쪽에서 처리하도록 하는 것)

예외 되던지기  과정

1. 예외가 발생할 가능성이 있는 메서드에서 try-catch문을 사용해서 예외를 처리해주고,
2. catch문에서 필요한 작업을 행한 후에 `throw`문을 사용해서 예외를 다시 발생시킨다.
3. 다시 발생한 예외는 이 메서드를 호출한 메서드에게 전달되고,
4. 호출한 메서드의 try-catch문에서 예외를 또다시 처리한다.

```java
class ExceptionEx17 {
    public static void main(String[] args) {
        try{
            method1();
        }catch(Exception e){
            System.out.println("main메서드에서 예외가 처리되었습니다.");
        }
    }
    static void method1() throws Exception{
        try{
            throw new Exception();
        } catch (Exception e){
            System.out.println("method1메서드에서 예외가 처리되었습니다.");
            throw e;        // 다시 예외를 발생시킨다.
        }
    }
}
/* 결과 method1에서 예외를 처리하고도 throw문을 통해 다시 예외를 발생 시켜 이 예외를 main메서드에서 한 번더 처리함
method1메서드에서 예외가 처리되었습니다.
main메서드에서 예외가 처리되었습니다.
*/
```

반환값이 있는 return문의 경우, catch블럭에도 return문이 있어야 한다. 예외가 발생 했을 경우에도 값을 반환해야하기 때문이다.

```java
static int method1(){
	try{
		System.out.println("method1()이 호출되었습니다.");
		return 0;		// 현재 실행 중인 메서드를 종료한다.
	} catch(Exception e){
		e.printStackTrace();
		return 1;		// catch블럭 내에도 return문이 필요하다.
	} finally{
		System.out.println("method1()의 finally블럭이 실행되었습니다.");
	}
 public static void main(String[] args) {
        System.out.println(method1());	// 예외가 발생하지 않으면 0, 예외가 발생하면 return 1에 의해 1출력
    }
}
```

또는 catch블럭에서 예외 되던지기를 해서 호출한 메서드로 예외를 전달하면, return문이 없어도 된다.(그래서 검증에서도 assert문 대신 AssertError를 생성해서 던진다)

```java
static int method1() throws Exception{
	try{
		System.out.println("method1()이 호출되었습니다.");
		return 0;		// 현재 실행 중인 메서드를 종료한다.
	} catch(Exception e){
		e.printStackTrace();
//		return 1;		// catch블럭 내에도 return문이 필요하다.
		throw new Exception();	// return문 대신 에외를 호출한 메서드로 전달
	} finally{
		System.out.println("method1()의 finally블럭이 실행되었습니다.");
	}
}
```

finally에도 리턴문 사용 가능, try블럭이나 catch블럭의 return 문 다음에 수행된다. 최종적으로 finally블럭 내의 return문의 값이 반환된다.

#### 1.12 연결된 예외(chained exception)

예외 A가 예외 B를 발생시켰다면, A를 B의 `원인 예외(cause exception)`이라고 한다.

다음 코드는 SpaceException을 원인 예외로 하는 InstallException을 발생시키는 방법을 보여준다.

```java
try{
	startInstall();		// SpaceException 발생
	copyFiles();
} catch (SpaceException e){
	InstallException ie = new InstallException("설치중 예외발생");		// 예외 생성
	ie.initCause(e);	// InstallException의 원인 예외를 SpaceException으로 지정
	throw ie;			// InstallException을 발생시킨다.
} catch (MemoryException me){
	...
}
```

```
// Exception클래스의 조상인 Throwable클래스에 정의 되어있음

Throwable initCause(Throwable cause)	지정한 예외를 원인 예외로 등록
Throwable getCause()					원인 예외를 반환
```

**원인 예외로 등록해서 다시 예외를 발생시키는 이유**

1.여러 예외를 하나로 묶어서 다루기 위해서

그렇다고 아래와 같이 InstallException을 SpaceException과 MemoryException의 조상으로 해서 catch블럭을 작성하면, 실제로 발생한 예외가 어떤 것인지 알 수 없다는 문제가 생긴다. 그리고  SpaceException과 MemoryException의 상속관계를 변경해야 한다는 것도 부담이다.

```java
try{
	startInstall();		// SpaceException발생
	copyFiles();
} catch (InstallException e)	{ // InstallException은
	e.printStackTrace();		//  SpaceException과 MemoryException의 조상
}
```

그래서 예외가 원인 예외를 포함할 수 있게 한 것이다. 이렇게 하면, 두 예외는 상속관계가 아니어도 상관x

```java
public class Throwable implements Serializable{
		...
	private Throwable cause = this;		// 객체 자신(this)을 원인 예외로 등록
    	...
    public synchronized Throwable initCause(Throwable cause){
            this.cause = cause;	// cause를 원인 예외로 등록
            return this;
        }
}
```

2.checked예외를 unchecked예외로 변경하려 할 때

```java
static void startInstall() throws SpaceExcepion, MemoryException{
	if(!enoughSpace())
		throw new SpaceException("설치할 공간이 부족합니다.");
	if(!enoughMemory())
		throw new MemoryException("메모리가 부족합니다.");
}
```

위 코드를 아래와 같이 바꿀수 있다.

```java
static void startInstall() throws SpaceExcepion
	if(!enoughSpace())
		throw new SpaceException("설치할 공간이 부족합니다.");
	if(!enoughMemory())
		throw new RuntimeException(new MemoryException("메모리가 부족합니다."));
}

/* 만약 RuntimeException대신 initCause를 사용한다면 다음과 같이해야함
   이 예제에서는 보다시피 많이 길어짐
		MemoryException memoryException = new MemoryException("메모리가 부족합니다.");
        RuntimeException runtimeException = new RuntimeException();
        runtimeException.initCause(memoryException);
        throw runtimeException;
   
*/
```

MemoryException은 Exception의 자손이므로 반드시 예외를 처리해야하는데, 이 예외를 RuntimeException으로 감싸버렸기 때문에 unchecked예외가 되었다. 그래서 더이상 예외를 선언하지 않아도 된다. 

initCause()대신 아래 코드를 사용

```java
RuntimeException(Throwable cause)	// 원인 예외를 등록하는 생성자
```

예제

```java
package ChEx;

public class ChainedExceptionEx {
    public static void main(String[] args) {
        try{
            install();
        }catch (InstallException e){
            e.printStackTrace();
        }catch (Exception e){
            e.printStackTrace();
        }
    }   // main 끝

    static void install() throws InstallException{
        try{
            startInstall();
            copyFiles();
        }catch (SpaceException se){
            InstallException ie = new InstallException("설치 중 예외발생");
            ie.initCause(se);
            throw ie;
        }catch (MemoryException me){
            InstallException ie = new InstallException("설치 중 예외발생");
            ie.initCause(me);
            throw  ie;
        }finally {
            deleteTempFiles();
        }
    }
    static void startInstall () throws SpaceException, MemoryException{
        if(!enoughSpace()){
            throw new SpaceException("설치할 공간이 부족합니다.");
        }
        if(!enoughMemory()){
            throw new MemoryException("메모리가 부족합니다.");
            // throw new RuntimeException(new MemoryException("메모리가 부족합니다."));
        }
    }
    static void copyFiles(){/* 파일들을 복사하는 코드를 적는다. */}
    static void deleteTempFiles(){/* 임시파일들을 삭제하는 코드를 적는다.*/}

    static boolean enoughSpace(){
        // 설치하는데 필요한 공간이 있는지 확인하는 코드를 적는다.
        return false;
    }
    static boolean enoughMemory(){
        // 설치하는데 필요한 메모리공간이 있는지 확인하는 코드를 적는다.
        return true;
    }
}
class InstallException extends Exception{
    InstallException(String msg){
        super(msg);
    }
}
class SpaceException extends Exception{
    SpaceException(String msg){
        super(msg);
    }
}
class MemoryException extends Exception{
    MemoryException(String msg){
        super(msg);
    }
}
/* 결과
-발생 예외
ChEx.InstallException: 설치 중 예외발생
	at ChEx.ChainedExceptionEx.install(ChainedExceptionEx.java:19)
	at ChEx.ChainedExceptionEx.main(ChainedExceptionEx.java:6)
-원인 예외
Caused by: ChEx.SpaceException: 설치할 공간이 부족합니다.
	at ChEx.ChainedExceptionEx.startInstall(ChainedExceptionEx.java:32)
	at ChEx.ChainedExceptionEx.install(ChainedExceptionEx.java:16)
	... 1 more
	
*/
```



